Workbook

Sheet WorkSheet_ANS
A1: OrderID | B1: Date | C1: Year | D1: Month | E1: CustomerName | F1: Region | G1: Country | H1: City | I1: ProductCategory | J1: ProductName | K1: SalesChannel | L1: SalesRep | M1: UnitPrice | N1: Quantity | O1: Discount | P1: DiscountType | Q1: Revenue | R1: OrderType | S1: PremiumOrder | T1: Cost | U1: Profit | V1: PaymentMethod | W1: OrderPriority | X1: ShipMode | Y1: ShippingCost | Z1: DeliveryDays | AA1: DeliveryType | AB1: CustomerSegment | AC1: Returned | AD1: Rating | AE1: ProductReview | AF1: SaleValue | AG1: Profit Margin | AQ1: Count total number of orders. | AY1: =COUNTA(WorkSheet_ANS!$A$1:$A$999) -> 999 | BC1: Count orders per Month.AND Calculate Revenue per Month.
A2: 1 | B2: 2023-08-26 | C2: =YEAR(Table2[[#This Row],[Date]]) -> 2023 | D2: =TEXT(Table2[[#This Row],[Date]],"mmmm") -> August | E2: Michael | F2: North | G2: Canada | H2: Mumbai | I2: Electronics | J2: Jacket | K2: Retail | L2: Rep D | M2: 576.66 | N2: 4 | O2: 0.17 | P2: =IF(Table2[[#This Row],[Discount]]>20%,"HIGH","LOW") -> LOW | Q2: 1914.51 | R2: =_xlfn.IFS(Table2[[#This Row],[Revenue]]<1000,"Small",OR(Table2[[#This Row],[Revenue]]>1000,Table2[[#This Row],[Revenue]]<=5000),"Medium",Table2[[#This Row],[Revenue]]>5000,"Large") -> Medium | S2: =IF(Table2[[#This Row],[Revenue]]>3000,"Premium","Not Premium") -> Not Premium | T2: 1118.63 | U2: 795.88 | V2: Bank Transfer | W2: Medium | X2: Standard | Y2: 32.48 | Z2: 10 | AA2: =IF(Table2[[#This Row],[DeliveryDays]]<=3,"FAST DELIVERY","LATE DELIVERY") -> LATE DELIVERY | AB2: Home Office | AC2: No | AD2: 2 | AE2: =_xlfn.IFS(Table2[[#This Row],[Rating]]=5,"Excellent",Table2[[#This Row],[Rating]]=4,"Good",Table2[[#This Row],[Rating]]=3,"Average",Table2[[#This Row],[Rating]]<=2,"Poor") -> Poor | AF2: =Table2[[#This Row],[Cost]]+Table2[[#This Row],[Profit]]+Table2[[#This Row],[ShippingCost]]+Table2[[#This Row],[DeliveryDays]] -> 1956.99 | AG2: =Table2[[#This Row],[Profit]]/Table2[[#This Row],[Cost]] -> 0.71147743 | BC2: Month | BD2: Orders | BE2: Revenue | BF2: SalesValue | BG2: Profit | BH2: GrowthRate
A3: 2 | B3: 2024-10-15 | C3: =YEAR(Table2[[#This Row],[Date]]) -> 2024 | D3: =TEXT(Table2[[#This Row],[Date]],"mmmm") -> October | E3: Priya | F3: South | G3: USA | H3: Berlin | I3: Electronics | J3: Jacket | K3: Online | L3: Rep C | M3: 447.27 | N3: 5 | O3: 0.12 | P3: =IF(Table2[[#This Row],[Discount]]>20%,"HIGH","LOW") -> LOW | Q3: 1967.99 | R3: =_xlfn.IFS(Table2[[#This Row],[Revenue]]<1000,"Small",OR(Table2[[#This Row],[Revenue]]>1000,Table2[[#This Row],[Revenue]]<=5000),"Medium",Table2[[#This Row],[Revenue]]>5000,"Large") -> Medium | S3: =IF(Table2[[#This Row],[Revenue]]>3000,"Premium","Not Premium") -> Not Premium | T3: 1337.43 | U3: 630.56 | V3: Credit Card | W3: Medium | X3: Same Day | Y3: 25.58 | Z3: 4 | AA3: =IF(Table2[[#This Row],[DeliveryDays]]<=3,"FAST DELIVERY","LATE DELIVERY") -> LATE DELIVERY | AB3: Home Office | AC3: No | AD3: 1 | AE3: =_xlfn.IFS(Table2[[#This Row],[Rating]]=5,"Excellent",Table2[[#This Row],[Rating]]=4,"Good",Table2[[#This Row],[Rating]]=3,"Average",Table2[[#This Row],[Rating]]<=2,"Poor") -> Poor | AF3: =Table2[[#This Row],[Cost]]+Table2[[#This Row],[Profit]]+Table2[[#This Row],[ShippingCost]]+Table2[[#This Row],[DeliveryDays]] -> 1997.57 | AG3: =Table2[[#This Row],[Profit]]/Table2[[#This Row],[Cost]] -> 0.4714714 | AQ3: Count how many customers appear in the dataset. | AY3: =COUNTA(WorkSheet_ANS!$E$1:$E$999) -> 999 | BC3: January | BD3: =COUNTIF(Table2[[#All],[Month]],$BC3) -> 72 | BE3: =SUMIF(Table2[Month],BC3,Table2[Revenue]) -> 305092.44 | BF3: =SUMIF(Table2[[#All],[Month]],BC3,Table2[[#All],[SaleValue]]) -> 307506.98 | BG3: =SUMIF(Table2[[#All],[Month]],BC3,Table2[[#All],[Profit]]) -> 97799.52 | BH3: 0
A4: 3 | B4: 2024-12-04 | C4: =YEAR(Table2[[#This Row],[Date]]) -> 2024 | D4: =TEXT(Table2[[#This Row],[Date]],"mmmm") -> December | E4: David | F4: North | G4: USA | H4: Mumbai | I4: Sports | J4: Keyboard | K4: Distributor | L4: Rep C | M4: 344.45 | N4: 19 | O4: 0.15 | P4: =IF(Table2[[#This Row],[Discount]]>20%,"HIGH","LOW") -> LOW | Q4: 5562.87 | R4: =_xlfn.IFS(Table2[[#This Row],[Revenue]]<1000,"Small",OR(Table2[[#This Row],[Revenue]]>1000,Table2[[#This Row],[Revenue]]<=5000),"Medium",Table2[[#This Row],[Revenue]]>5000,"Large") -> Medium | S4: =IF(Table2[[#This Row],[Revenue]]>3000,"Premium","Not Premium") -> Premium | T4: 4009.72 | U4: 1553.15 | V4: Credit Card | W4: Critical | X4: Standard | Y4: 27.68 | Z4: 1 | AA4: =IF(Table2[[#This Row],[DeliveryDays]]<=3,"FAST DELIVERY","LATE DELIVERY") -> FAST DELIVERY | AB4: Corporate | AC4: Yes | AD4: 1 | AE4: =_xlfn.IFS(Table2[[#This Row],[Rating]]=5,"Excellent",Table2[[#This Row],[Rating]]=4,"Good",Table2[[#This Row],[Rating]]=3,"Average",Table2[[#This Row],[Rating]]<=2,"Poor") -> Poor | AF4: =Table2[[#This Row],[Cost]]+Table2[[#This Row],[Profit]]+Table2[[#This Row],[ShippingCost]]+Table2[[#This Row],[DeliveryDays]] -> 5591.55 | AG4: =Table2[[#This Row],[Profit]]/Table2[[#This Row],[Cost]] -> 0.38734625 | BC4: February | BD4: =COUNTIF(Table2[[#All],[Month]],$BC4) -> 68 | BE4: =SUMIF(Table2[Month],BC4,Table2[Revenue]) -> 324240.36 | BF4: =SUMIF(Table2[[#All],[Month]],BC4,Table2[[#All],[SaleValue]]) -> 326483.54 | BG4: =SUMIF(Table2[[#All],[Month]],BC4,Table2[[#All],[Profit]]) -> 95325.45 | BH4: =(BE4-BE3)/BE3 -> 0.062761044
A5: 4 | B5: 2023-01-07 | C5: =YEAR(Table2[[#This Row],[Date]]) -> 2023 | D5: =TEXT(Table2[[#This Row],[Date]],"mmmm") -> January | E5: Riya | F5: South | G5: India | H5: Sydney | I5: Furniture | J5: Chair | K5: Retail | L5: Rep D | M5: 438.12 | N5: 16 | O5: 0.28 | P5: =IF(Table2[[#This Row],[Discount]]>20%,"HIGH","LOW") -> HIGH | Q5: 5047.14 | R5: =_xlfn.IFS(Table2[[#This Row],[Revenue]]<1000,"Small",OR(Table2[[#This Row],[Revenue]]>1000,Table2[[#This Row],[Revenue]]<=5000),"Medium",Table2[[#This Row],[Revenue]]>5000,"Large") -> Medium | S5: =IF(Table2[[#This Row],[Revenue]]>3000,"Premium","Not Premium") -> Premium | T5: 2684.67 | U5: 2362.47 | V5: PayPal | W5: Critical | X5: Same Day | Y5: 23.41 | Z5: 3 | AA5: =IF(Table2[[#This Row],[DeliveryDays]]<=3,"FAST DELIVERY","LATE DELIVERY") -> FAST DELIVERY | AB5: Home Office | AC5: Yes | AD5: 1 | AE5: =_xlfn.IFS(Table2[[#This Row],[Rating]]=5,"Excellent",Table2[[#This Row],[Rating]]=4,"Good",Table2[[#This Row],[Rating]]=3,"Average",Table2[[#This Row],[Rating]]<=2,"Poor") -> Poor | AF5: =Table2[[#This Row],[Cost]]+Table2[[#This Row],[Profit]]+Table2[[#This Row],[ShippingCost]]+Table2[[#This Row],[DeliveryDays]] -> 5073.55 | AG5: =Table2[[#This Row],[Profit]]/Table2[[#This Row],[Cost]] -> 0.87998525 | AQ5: Count orders where Returned = Yes. | AY5: =COUNTIF(WorkSheet_ANS!$AC$1:$AC$999,"Yes") -> 499 | BC5: March | BD5: =COUNTIF(Table2[[#All],[Month]],$BC5) -> 89 | BE5: =SUMIF(Table2[Month],BC5,Table2[Revenue]) -> 345517.57 | BF5: =SUMIF(Table2[[#All],[Month]],BC5,Table2[[#All],[SaleValue]]) -> 348582.49 | BG5: =SUMIF(Table2[[#All],[Month]],BC5,Table2[[#All],[Profit]]) -> 111728.88 | BH5: =(BE5-BE4)/BE4 -> 0.06562172
A6: 5 | B6: 2024-05-25 | C6: =YEAR(Table2[[#This Row],[Date]]) -> 2024 | D6: =TEXT(Table2[[#This Row],[Date]],"mmmm") -> May | E6: Sophia | F6: East | G6: India | H6: Pune | I6: Office Supplies | J6: Desk | K6: Retail | L6: Rep A | M6: 80.22 | N6: 15 | O6: 0 | P6: =IF(Table2[[#This Row],[Discount]]>20%,"HIGH","LOW") -> LOW | Q6: 1203.3 | R6: =_xlfn.IFS(Table2[[#This Row],[Revenue]]<1000,"Small",OR(Table2[[#This Row],[Revenue]]>1000,Table2[[#This Row],[Revenue]]<=5000),"Medium",Table2[[#This Row],[Revenue]]>5000,"Large") -> Medium | S6: =IF(Table2[[#This Row],[Revenue]]>3000,"Premium","Not Premium") -> Not Premium | T6: 745.46 | U6: 457.84 | V6: Bank Transfer | W6: Low | X6: Express | Y6: 29.52 | Z6: 8 | AA6: =IF(Table2[[#This Row],[DeliveryDays]]<=3,"FAST DELIVERY","LATE DELIVERY") -> LATE DELIVERY | AB6: Home Office | AC6: Yes | AD6: 1 | AE6: =_xlfn.IFS(Table2[[#This Row],[Rating]]=5,"Excellent",Table2[[#This Row],[Rating]]=4,"Good",Table2[[#This Row],[Rating]]=3,"Average",Table2[[#This Row],[Rating]]<=2,"Poor") -> Poor | AF6: =Table2[[#This Row],[Cost]]+Table2[[#This Row],[Profit]]+Table2[[#This Row],[ShippingCost]]+Table2[[#This Row],[DeliveryDays]] -> 1240.82 | AG6: =Table2[[#This Row],[Profit]]/Table2[[#This Row],[Cost]] -> 0.61417112 | BC6: April | BD6: =COUNTIF(Table2[[#All],[Month]],$BC6) -> 78 | BE6: =SUMIF(Table2[Month],BC6,Table2[Revenue]) -> 245976.51 | BF6: =SUMIF(Table2[[#All],[Month]],BC6,Table2[[#All],[SaleValue]]) -> 248734.52 | BG6: =SUMIF(Table2[[#All],[Month]],BC6,Table2[[#All],[Profit]]) -> 71169.89 | BH6: =(BE6-BE5)/BE5 -> -0.28809261
A7: 6 | B7: 2023-05-07 | C7: =YEAR(Table2[[#This Row],[Date]]) -> 2023 | D7: =TEXT(Table2[[#This Row],[Date]],"mmmm") -> May | E7: Riya | F7: East | G7: India | H7: Delhi | I7: Clothing | J7: Jacket | K7: Distributor | L7: Rep A | M7: 956.16 | N7: 2 | O7: 0 | P7: =IF(Table2[[#This Row],[Discount]]>20%,"HIGH","LOW") -> LOW | Q7: 1912.32 | R7: =_xlfn.IFS(Table2[[#This Row],[Revenue]]<1000,"Small",OR(Table2[[#This Row],[Revenue]]>1000,Table2[[#This Row],[Revenue]]<=5000),"Medium",Table2[[#This Row],[Revenue]]>5000,"Large") -> Medium | S7: =IF(Table2[[#This Row],[Revenue]]>3000,"Premium","Not Premium") -> Not Premium | T7: 1376.98 | U7: 535.34 | V7: Cash | W7: Low | X7: Express | Y7: 7.77 | Z7: 2 | AA7: =IF(Table2[[#This Row],[DeliveryDays]]<=3,"FAST DELIVERY","LATE DELIVERY") -> FAST DELIVERY | AB7: Corporate | AC7: Yes | AD7: 4 | AE7: =_xlfn.IFS(Table2[[#This Row],[Rating]]=5,"Excellent",Table2[[#This Row],[Rating]]=4,"Good",Table2[[#This Row],[Rating]]=3,"Average",Table2[[#This Row],[Rating]]<=2,"Poor") -> Good | AF7: =Table2[[#This Row],[Cost]]+Table2[[#This Row],[Profit]]+Table2[[#This Row],[ShippingCost]]+Table2[[#This Row],[DeliveryDays]] -> 1922.09 | AG7: =Table2[[#This Row],[Profit]]/Table2[[#This Row],[Cost]] -> 0.38877834 | AQ7: Count orders where Returned = No. | AY7: =COUNTIF(WorkSheet_ANS!$AC$1:$AC$999,"No") -> 499 | BC7: May | BD7: =COUNTIF(Table2[[#All],[Month]],$BC7) -> 96 | BE7: =SUMIF(Table2[Month],BC7,Table2[Revenue]) -> 463426.5 | BF7: =SUMIF(Table2[[#All],[Month]],BC7,Table2[[#All],[SaleValue]]) -> 466286.82 | BG7: =SUMIF(Table2[[#All],[Month]],BC7,Table2[[#All],[Profit]]) -> 145553.43 | BH7: =(BE7-BE6)/BE6 -> 0.88402746
A8: 7 | B8: 2024-06-19 | C8: =YEAR(Table2[[#This Row],[Date]]) -> 2024 | D8: =TEXT(Table2[[#This Row],[Date]],"mmmm") -> June | E8: David | F8: East | G8: India | H8: New York | I8: Office Supplies | J8: Tablet | K8: Retail | L8: Rep B | M8: 342.02 | N8: 20 | O8: 0.08 | P8: =IF(Table2[[#This Row],[Discount]]>20%,"HIGH","LOW") -> LOW | Q8: 6293.17 | R8: =_xlfn.IFS(Table2[[#This Row],[Revenue]]<1000,"Small",OR(Table2[[#This Row],[Revenue]]>1000,Table2[[#This Row],[Revenue]]<=5000),"Medium",Table2[[#This Row],[Revenue]]>5000,"Large") -> Medium | S8: =IF(Table2[[#This Row],[Revenue]]>3000,"Premium","Not Premium") -> Premium | T8: 3483.81 | U8: 2809.36 | V8: Cash | W8: Low | X8: Standard | Y8: 32.24 | Z8: 2 | AA8: =IF(Table2[[#This Row],[DeliveryDays]]<=3,"FAST DELIVERY","LATE DELIVERY") -> FAST DELIVERY | AB8: Home Office | AC8: Yes | AD8: 3 | AE8: =_xlfn.IFS(Table2[[#This Row],[Rating]]=5,"Excellent",Table2[[#This Row],[Rating]]=4,"Good",Table2[[#This Row],[Rating]]=3,"Average",Table2[[#This Row],[Rating]]<=2,"Poor") -> Average | AF8: =Table2[[#This Row],[Cost]]+Table2[[#This Row],[Profit]]+Table2[[#This Row],[ShippingCost]]+Table2[[#This Row],[DeliveryDays]] -> 6327.41 | AG8: =Table2[[#This Row],[Profit]]/Table2[[#This Row],[Cost]] -> 0.80640448 | BC8: June | BD8: =COUNTIF(Table2[[#All],[Month]],$BC8) -> 91 | BE8: =SUMIF(Table2[Month],BC8,Table2[Revenue]) -> 323348.37 | BF8: =SUMIF(Table2[[#All],[Month]],BC8,Table2[[#All],[SaleValue]]) -> 326385.37 | BG8: =SUMIF(Table2[[#All],[Month]],BC8,Table2[[#All],[Profit]]) -> 93950.05 | BH8: =(BE8-BE7)/BE7 -> -0.30226612
A9: 8 | B9: 2024-09-25 | C9: =YEAR(Table2[[#This Row],[Date]]) -> 2024 | D9: =TEXT(Table2[[#This Row],[Date]],"mmmm") -> September | E9: Sophia | F9: West | G9: Germany | H9: Mumbai | I9: Furniture | J9: T-Shirt | K9: Retail | L9: Rep E | M9: 380.23 | N9: 5 | O9: 0.01 | P9: =IF(Table2[[#This Row],[Discount]]>20%,"HIGH","LOW") -> LOW | Q9: 1882.14 | R9: =_xlfn.IFS(Table2[[#This Row],[Revenue]]<1000,"Small",OR(Table2[[#This Row],[Revenue]]>1000,Table2[[#This Row],[Revenue]]<=5000),"Medium",Table2[[#This Row],[Revenue]]>5000,"Large") -> Medium | S9: =IF(Table2[[#This Row],[Revenue]]>3000,"Premium","Not Premium") -> Not Premium | T9: 1181.3 | U9: 700.84 | V9: Cash | W9: Medium | X9: Express | Y9: 28.33 | Z9: 4 | AA9: =IF(Table2[[#This Row],[DeliveryDays]]<=3,"FAST DELIVERY","LATE DELIVERY") -> LATE DELIVERY | AB9: Home Office | AC9: Yes | AD9: 2 | AE9: =_xlfn.IFS(Table2[[#This Row],[Rating]]=5,"Excellent",Table2[[#This Row],[Rating]]=4,"Good",Table2[[#This Row],[Rating]]=3,"Average",Table2[[#This Row],[Rating]]<=2,"Poor") -> Poor | AF9: =Table2[[#This Row],[Cost]]+Table2[[#This Row],[Profit]]+Table2[[#This Row],[ShippingCost]]+Table2[[#This Row],[DeliveryDays]] -> 1914.47 | AG9: =Table2[[#This Row],[Profit]]/Table2[[#This Row],[Cost]] -> 0.59327859 | AQ9: Find the average UnitPrice. | AY9: =AVERAGE(WorkSheet_ANS!$M$1:$M$999) -> 498.02772 | BC9: July | BD9: =COUNTIF(Table2[[#All],[Month]],$BC9) -> 92 | BE9: =SUMIF(Table2[Month],BC9,Table2[Revenue]) -> 478422.08 | BF9: =SUMIF(Table2[[#All],[Month]],BC9,Table2[[#All],[SaleValue]]) -> 481599.27 | BG9: =SUMIF(Table2[[#All],[Month]],BC9,Table2[[#All],[Profit]]) -> 139079.79 | BH9: =(BE9-BE8)/BE8 -> 0.47958711
A10: 9 | B10: 2023-07-24 | C10: =YEAR(Table2[[#This Row],[Date]]) -> 2023 | D10: =TEXT(Table2[[#This Row],[Date]],"mmmm") -> July | E10: Riya | F10: North | G10: Canada | H10: New York | I10: Furniture | J10: Football | K10: Online | L10: Rep D | M10: 604.76 | N10: 19 | O10: 0.18 | P10: =IF(Table2[[#This Row],[Discount]]>20%,"HIGH","LOW") -> LOW | Q10: 9422.16 | R10: =_xlfn.IFS(Table2[[#This Row],[Revenue]]<1000,"Small",OR(Table2[[#This Row],[Revenue]]>1000,Table2[[#This Row],[Revenue]]<=5000),"Medium",Table2[[#This Row],[Revenue]]>5000,"Large") -> Medium | S10: =IF(Table2[[#This Row],[Revenue]]>3000,"Premium","Not Premium") -> Premium | T10: 7639.72 | U10: 1782.44 | V10: Bank Transfer | W10: High | X10: Same Day | Y10: 29.33 | Z10: 8 | AA10: =IF(Table2[[#This Row],[DeliveryDays]]<=3,"FAST DELIVERY","LATE DELIVERY") -> LATE DELIVERY | AB10: Corporate | AC10: No | AD10: 3 | AE10: =_xlfn.IFS(Table2[[#This Row],[Rating]]=5,"Excellent",Table2[[#This Row],[Rating]]=4,"Good",Table2[[#This Row],[Rating]]=3,"Average",Table2[[#This Row],[Rating]]<=2,"Poor") -> Average | AF10: =Table2[[#This Row],[Cost]]+Table2[[#This Row],[Profit]]+Table2[[#This Row],[ShippingCost]]+Table2[[#This Row],[DeliveryDays]] -> 9459.49 | AG10: =Table2[[#This Row],[Profit]]/Table2[[#This Row],[Cost]] -> 0.23331222 | BC10: August | BD10: =COUNTIF(Table2[[#All],[Month]],$BC10) -> 71 | BE10: =SUMIF(Table2[Month],BC10,Table2[Revenue]) -> 375497.65 | BF10: =SUMIF(Table2[[#All],[Month]],BC10,Table2[[#All],[SaleValue]]) -> 377733.91 | BG10: =SUMIF(Table2[[#All],[Month]],BC10,Table2[[#All],[Profit]]) -> 109707.94 | BH10: =(BE10-BE9)/BE9 -> -0.21513311
A11: 10 | B11: 2024-06-15 | C11: =YEAR(Table2[[#This Row],[Date]]) -> 2024 | D11: =TEXT(Table2[[#This Row],[Date]],"mmmm") -> June | E11: Riya | F11: South | G11: UK | H11: New York | I11: Office Supplies | J11: Jacket | K11: Retail | L11: Rep A | M11: 208.71 | N11: 9 | O11: 0.03 | P11: =IF(Table2[[#This Row],[Discount]]>20%,"HIGH","LOW") -> LOW | Q11: 1822.04 | R11: =_xlfn.IFS(Table2[[#This Row],[Revenue]]<1000,"Small",OR(Table2[[#This Row],[Revenue]]>1000,Table2[[#This Row],[Revenue]]<=5000),"Medium",Table2[[#This Row],[Revenue]]>5000,"Large") -> Medium | S11: =IF(Table2[[#This Row],[Revenue]]>3000,"Premium","Not Premium") -> Not Premium | T11: 1557.66 | U11: 264.38 | V11: UPI | W11: Medium | X11: Standard | Y11: 39.26 | Z11: 2 | AA11: =IF(Table2[[#This Row],[DeliveryDays]]<=3,"FAST DELIVERY","LATE DELIVERY") -> FAST DELIVERY | AB11: Home Office | AC11: No | AD11: 3 | AE11: =_xlfn.IFS(Table2[[#This Row],[Rating]]=5,"Excellent",Table2[[#This Row],[Rating]]=4,"Good",Table2[[#This Row],[Rating]]=3,"Average",Table2[[#This Row],[Rating]]<=2,"Poor") -> Average | AF11: =Table2[[#This Row],[Cost]]+Table2[[#This Row],[Profit]]+Table2[[#This Row],[ShippingCost]]+Table2[[#This Row],[DeliveryDays]] -> 1863.3 | AG11: =Table2[[#This Row],[Profit]]/Table2[[#This Row],[Cost]] -> 0.16972895 | AQ11: Find the maximum UnitPrice. | AY11: =MAX(WorkSheet_ANS!$M$1:$M$999) -> 999.66 | BC11: September | BD11: =COUNTIF(Table2[[#All],[Month]],$BC11) -> 86 | BE11: =SUMIF(Table2[Month],BC11,Table2[Revenue]) -> 398941.79 | BF11: =SUMIF(Table2[[#All],[Month]],BC11,Table2[[#All],[SaleValue]]) -> 401921.06 | BG11: =SUMIF(Table2[[#All],[Month]],BC11,Table2[[#All],[Profit]]) -> 126603.59 | BH11: =(BE11-BE10)/BE10 -> 0.062434851
A12: 11 | B12: 2023-02-07 | C12: =YEAR(Table2[[#This Row],[Date]]) -> 2023 | D12: =TEXT(Table2[[#This Row],[Date]],"mmmm") -> February | E12: Priya | F12: North | G12: Australia | H12: London | I12: Office Supplies | J12: Football | K12: Online | L12: Rep A | M12: 324.88 | N12: 16 | O12: 0.17 | P12: =IF(Table2[[#This Row],[Discount]]>20%,"HIGH","LOW") -> LOW | Q12: 4314.41 | R12: =_xlfn.IFS(Table2[[#This Row],[Revenue]]<1000,"Small",OR(Table2[[#This Row],[Revenue]]>1000,Table2[[#This Row],[Revenue]]<=5000),"Medium",Table2[[#This Row],[Revenue]]>5000,"Large") -> Medium | S12: =IF(Table2[[#This Row],[Revenue]]>3000,"Premium","Not Premium") -> Premium | T12: 3303.81 | U12: 1010.6 | V12: Bank Transfer | W12: Low | X12: Same Day | Y12: 33.2 | Z12: 4 | AA12: =IF(Table2[[#This Row],[DeliveryDays]]<=3,"FAST DELIVERY","LATE DELIVERY") -> LATE DELIVERY | AB12: Corporate | AC12: No | AD12: 4 | AE12: =_xlfn.IFS(Table2[[#This Row],[Rating]]=5,"Excellent",Table2[[#This Row],[Rating]]=4,"Good",Table2[[#This Row],[Rating]]=3,"Average",Table2[[#This Row],[Rating]]<=2,"Poor") -> Good | AF12: =Table2[[#This Row],[Cost]]+Table2[[#This Row],[Profit]]+Table2[[#This Row],[ShippingCost]]+Table2[[#This Row],[DeliveryDays]] -> 4351.61 | AG12: =Table2[[#This Row],[Profit]]/Table2[[#This Row],[Cost]] -> 0.30588926 | BC12: October | BD12: =COUNTIF(Table2[[#All],[Month]],$BC12) -> 84 | BE12: =SUMIF(Table2[Month],BC12,Table2[Revenue]) -> 397456.12 | BF12: =SUMIF(Table2[[#All],[Month]],BC12,Table2[[#All],[SaleValue]]) -> 400276.68 | BG12: =SUMIF(Table2[[#All],[Month]],BC12,Table2[[#All],[Profit]]) -> 125919.31 | BH12: =(BE12-BE11)/BE11 -> -0.003724027
A13: 12 | B13: 2024-07-22 | C13: =YEAR(Table2[[#This Row],[Date]]) -> 2024 | D13: =TEXT(Table2[[#This Row],[Date]],"mmmm") -> July | E13: Sara | F13: East | G13: Australia | H13: Sydney | I13: Sports | J13: Chair | K13: Online | L13: Rep D | M13: 89.82 | N13: 12 | O13: 0.16 | P13: =IF(Table2[[#This Row],[Discount]]>20%,"HIGH","LOW") -> LOW | Q13: 905.39 | R13: =_xlfn.IFS(Table2[[#This Row],[Revenue]]<1000,"Small",OR(Table2[[#This Row],[Revenue]]>1000,Table2[[#This Row],[Revenue]]<=5000),"Medium",Table2[[#This Row],[Revenue]]>5000,"Large") -> Small | S13: =IF(Table2[[#This Row],[Revenue]]>3000,"Premium","Not Premium") -> Not Premium | T13: 594.91 | U13: 310.48 | V13: Bank Transfer | W13: Medium | X13: Same Day | Y13: 13.9 | Z13: 8 | AA13: =IF(Table2[[#This Row],[DeliveryDays]]<=3,"FAST DELIVERY","LATE DELIVERY") -> LATE DELIVERY | AB13: Consumer | AC13: No | AD13: 4 | AE13: =_xlfn.IFS(Table2[[#This Row],[Rating]]=5,"Excellent",Table2[[#This Row],[Rating]]=4,"Good",Table2[[#This Row],[Rating]]=3,"Average",Table2[[#This Row],[Rating]]<=2,"Poor") -> Good | AF13: =Table2[[#This Row],[Cost]]+Table2[[#This Row],[Profit]]+Table2[[#This Row],[ShippingCost]]+Table2[[#This Row],[DeliveryDays]] -> 927.29 | AG13: =Table2[[#This Row],[Profit]]/Table2[[#This Row],[Cost]] -> 0.52189407 | AQ13: Find the minimum UnitPrice. | AY13: =MIN(WorkSheet_ANS!$M$1:$M$999) -> 12.57 | BC13: November | BD13: =COUNTIF(Table2[[#All],[Month]],$BC13) -> 71 | BE13: =SUMIF(Table2[Month],BC13,Table2[Revenue]) -> 298662.64 | BF13: =SUMIF(Table2[[#All],[Month]],BC13,Table2[[#All],[SaleValue]]) -> 300850.43 | BG13: =SUMIF(Table2[[#All],[Month]],BC13,Table2[[#All],[Profit]]) -> 85355.5 | BH13: =(BE13-BE12)/BE12 -> -0.2485645
A14: 13 | B14: 2023-06-12 | C14: =YEAR(Table2[[#This Row],[Date]]) -> 2023 | D14: =TEXT(Table2[[#This Row],[Date]],"mmmm") -> June | E14: Anita | F14: West | G14: Germany | H14: Toronto | I14: Clothing | J14: Jacket | K14: Distributor | L14: Rep B | M14: 387.73 | N14: 6 | O14: 0.19 | P14: =IF(Table2[[#This Row],[Discount]]>20%,"HIGH","LOW") -> LOW | Q14: 1884.37 | R14: =_xlfn.IFS(Table2[[#This Row],[Revenue]]<1000,"Small",OR(Table2[[#This Row],[Revenue]]>1000,Table2[[#This Row],[Revenue]]<=5000),"Medium",Table2[[#This Row],[Revenue]]>5000,"Large") -> Medium | S14: =IF(Table2[[#This Row],[Revenue]]>3000,"Premium","Not Premium") -> Not Premium | T14: 1273.7 | U14: 610.67 | V14: PayPal | W14: Medium | X14: Standard | Y14: 20.17 | Z14: 1 | AA14: =IF(Table2[[#This Row],[DeliveryDays]]<=3,"FAST DELIVERY","LATE DELIVERY") -> FAST DELIVERY | AB14: Consumer | AC14: Yes | AD14: 2 | AE14: =_xlfn.IFS(Table2[[#This Row],[Rating]]=5,"Excellent",Table2[[#This Row],[Rating]]=4,"Good",Table2[[#This Row],[Rating]]=3,"Average",Table2[[#This Row],[Rating]]<=2,"Poor") -> Poor | AF14: =Table2[[#This Row],[Cost]]+Table2[[#This Row],[Profit]]+Table2[[#This Row],[ShippingCost]]+Table2[[#This Row],[DeliveryDays]] -> 1905.54 | AG14: =Table2[[#This Row],[Profit]]/Table2[[#This Row],[Cost]] -> 0.47944571 | BC14: December | BD14: =COUNTIF(Table2[[#All],[Month]],$BC14) -> 100 | BE14: =SUMIF(Table2[Month],BC14,Table2[Revenue]) -> 444211.16 | BF14: =SUMIF(Table2[[#All],[Month]],BC14,Table2[[#All],[SaleValue]]) -> 447548.01 | BG14: =SUMIF(Table2[[#All],[Month]],BC14,Table2[[#All],[Profit]]) -> 129365.17 | BH14: =(BE14-BE13)/BE13 -> 0.4873342
A15: 14 | B15: 2023-03-30 | C15: =YEAR(Table2[[#This Row],[Date]]) -> 2023 | D15: =TEXT(Table2[[#This Row],[Date]],"mmmm") -> March | E15: Anita | F15: North | G15: Germany | H15: Toronto | I15: Clothing | J15: Laptop | K15: Retail | L15: Rep E | M15: 49.49 | N15: 12 | O15: 0.18 | P15: =IF(Table2[[#This Row],[Discount]]>20%,"HIGH","LOW") -> LOW | Q15: 486.98 | R15: =_xlfn.IFS(Table2[[#This Row],[Revenue]]<1000,"Small",OR(Table2[[#This Row],[Revenue]]>1000,Table2[[#This Row],[Revenue]]<=5000),"Medium",Table2[[#This Row],[Revenue]]>5000,"Large") -> Small | S15: =IF(Table2[[#This Row],[Revenue]]>3000,"Premium","Not Premium") -> Not Premium | T15: 396.26 | U15: 90.72 | V15: Cash | W15: Low | X15: Standard | Y15: 28.4 | Z15: 5 | AA15: =IF(Table2[[#This Row],[DeliveryDays]]<=3,"FAST DELIVERY","LATE DELIVERY") -> LATE DELIVERY | AB15: Home Office | AC15: Yes | AD15: 3 | AE15: =_xlfn.IFS(Table2[[#This Row],[Rating]]=5,"Excellent",Table2[[#This Row],[Rating]]=4,"Good",Table2[[#This Row],[Rating]]=3,"Average",Table2[[#This Row],[Rating]]<=2,"Poor") -> Average | AF15: =Table2[[#This Row],[Cost]]+Table2[[#This Row],[Profit]]+Table2[[#This Row],[ShippingCost]]+Table2[[#This Row],[DeliveryDays]] -> 520.38 | AG15: =Table2[[#This Row],[Profit]]/Table2[[#This Row],[Cost]] -> 0.22894059 | AQ15: Find average Quantity sold per order. | AY15: =AVERAGE(WorkSheet_ANS!$N$2:$N$999) -> 10.498998
A16: 15 | B16: 2023-06-14 | C16: =YEAR(Table2[[#This Row],[Date]]) -> 2023 | D16: =TEXT(Table2[[#This Row],[Date]],"mmmm") -> June | E16: Priya | F16: South | G16: Canada | H16: London | I16: Electronics | J16: T-Shirt | K16: Distributor | L16: Rep E | M16: 66.03 | N16: 4 | O16: 0.03 | P16: =IF(Table2[[#This Row],[Discount]]>20%,"HIGH","LOW") -> LOW | Q16: 256.2 | R16: =_xlfn.IFS(Table2[[#This Row],[Revenue]]<1000,"Small",OR(Table2[[#This Row],[Revenue]]>1000,Table2[[#This Row],[Revenue]]<=5000),"Medium",Table2[[#This Row],[Revenue]]>5000,"Large") -> Small | S16: =IF(Table2[[#This Row],[Revenue]]>3000,"Premium","Not Premium") -> Not Premium | T16: 228.6 | U16: 27.6 | V16: Bank Transfer | W16: Low | X16: Same Day | Y16: 18.99 | Z16: 4 | AA16: =IF(Table2[[#This Row],[DeliveryDays]]<=3,"FAST DELIVERY","LATE DELIVERY") -> LATE DELIVERY | AB16: Consumer | AC16: Yes | AD16: 3 | AE16: =_xlfn.IFS(Table2[[#This Row],[Rating]]=5,"Excellent",Table2[[#This Row],[Rating]]=4,"Good",Table2[[#This Row],[Rating]]=3,"Average",Table2[[#This Row],[Rating]]<=2,"Poor") -> Average | AF16: =Table2[[#This Row],[Cost]]+Table2[[#This Row],[Profit]]+Table2[[#This Row],[ShippingCost]]+Table2[[#This Row],[DeliveryDays]] -> 279.19 | AG16: =Table2[[#This Row],[Profit]]/Table2[[#This Row],[Cost]] -> 0.12073491 | BC16: Find Month with highest revenue.
A17: 16 | B17: 2024-12-25 | C17: =YEAR(Table2[[#This Row],[Date]]) -> 2024 | D17: =TEXT(Table2[[#This Row],[Date]],"mmmm") -> December | E17: Michael | F17: North | G17: Canada | H17: Berlin | I17: Clothing | J17: Football | K17: Retail | L17: Rep E | M17: 687.05 | N17: 19 | O17: 0.18 | P17: =IF(Table2[[#This Row],[Discount]]>20%,"HIGH","LOW") -> LOW | Q17: 10704.24 | R17: =_xlfn.IFS(Table2[[#This Row],[Revenue]]<1000,"Small",OR(Table2[[#This Row],[Revenue]]>1000,Table2[[#This Row],[Revenue]]<=5000),"Medium",Table2[[#This Row],[Revenue]]>5000,"Large") -> Medium | S17: =IF(Table2[[#This Row],[Revenue]]>3000,"Premium","Not Premium") -> Premium | T17: 7654.15 | U17: 3050.09 | V17: Credit Card | W17: High | X17: Express | Y17: 25.82 | Z17: 3 | AA17: =IF(Table2[[#This Row],[DeliveryDays]]<=3,"FAST DELIVERY","LATE DELIVERY") -> FAST DELIVERY | AB17: Corporate | AC17: Yes | AD17: 3 | AE17: =_xlfn.IFS(Table2[[#This Row],[Rating]]=5,"Excellent",Table2[[#This Row],[Rating]]=4,"Good",Table2[[#This Row],[Rating]]=3,"Average",Table2[[#This Row],[Rating]]<=2,"Poor") -> Average | AF17: =Table2[[#This Row],[Cost]]+Table2[[#This Row],[Profit]]+Table2[[#This Row],[ShippingCost]]+Table2[[#This Row],[DeliveryDays]] -> 10733.06 | AG17: =Table2[[#This Row],[Profit]]/Table2[[#This Row],[Cost]] -> 0.3984884 | AQ17: Find maximum Quantity sold. | AY17: =MAX(WorkSheet_ANS!$N$2:$N$999) -> 20
A18: 17 | B18: 2023-08-05 | C18: =YEAR(Table2[[#This Row],[Date]]) -> 2023 | D18: =TEXT(Table2[[#This Row],[Date]],"mmmm") -> August | E18: Priya | F18: North | G18: Canada | H18: Pune | I18: Clothing | J18: Football | K18: Distributor | L18: Rep E | M18: 725.8 | N18: 8 | O18: 0.15 | P18: =IF(Table2[[#This Row],[Discount]]>20%,"HIGH","LOW") -> LOW | Q18: 4935.44 | R18: =_xlfn.IFS(Table2[[#This Row],[Revenue]]<1000,"Small",OR(Table2[[#This Row],[Revenue]]>1000,Table2[[#This Row],[Revenue]]<=5000),"Medium",Table2[[#This Row],[Revenue]]>5000,"Large") -> Medium | S18: =IF(Table2[[#This Row],[Revenue]]>3000,"Premium","Not Premium") -> Premium | T18: 3662.25 | U18: 1273.19 | V18: Bank Transfer | W18: Critical | X18: Same Day | Y18: 29.54 | Z18: 6 | AA18: =IF(Table2[[#This Row],[DeliveryDays]]<=3,"FAST DELIVERY","LATE DELIVERY") -> LATE DELIVERY | AB18: Corporate | AC18: Yes | AD18: 1 | AE18: =_xlfn.IFS(Table2[[#This Row],[Rating]]=5,"Excellent",Table2[[#This Row],[Rating]]=4,"Good",Table2[[#This Row],[Rating]]=3,"Average",Table2[[#This Row],[Rating]]<=2,"Poor") -> Poor | AF18: =Table2[[#This Row],[Cost]]+Table2[[#This Row],[Profit]]+Table2[[#This Row],[ShippingCost]]+Table2[[#This Row],[DeliveryDays]] -> 4970.98 | AG18: =Table2[[#This Row],[Profit]]/Table2[[#This Row],[Cost]] -> 0.3476524 | BC18: Highest revenue | BD18: Month
A19: 18 | B19: 2024-11-09 | C19: =YEAR(Table2[[#This Row],[Date]]) -> 2024 | D19: =TEXT(Table2[[#This Row],[Date]],"mmmm") -> November | E19: Sophia | F19: South | G19: UK | H19: London | I19: Sports | J19: Printer | K19: Retail | L19: Rep D | M19: 370.13 | N19: 1 | O19: 0.12 | P19: =IF(Table2[[#This Row],[Discount]]>20%,"HIGH","LOW") -> LOW | Q19: 325.71 | R19: =_xlfn.IFS(Table2[[#This Row],[Revenue]]<1000,"Small",OR(Table2[[#This Row],[Revenue]]>1000,Table2[[#This Row],[Revenue]]<=5000),"Medium",Table2[[#This Row],[Revenue]]>5000,"Large") -> Small | S19: =IF(Table2[[#This Row],[Revenue]]>3000,"Premium","Not Premium") -> Not Premium | T19: 263 | U19: 62.71 | V19: Cash | W19: Critical | X19: Standard | Y19: 40.28 | Z19: 9 | AA19: =IF(Table2[[#This Row],[DeliveryDays]]<=3,"FAST DELIVERY","LATE DELIVERY") -> LATE DELIVERY | AB19: Corporate | AC19: No | AD19: 4 | AE19: =_xlfn.IFS(Table2[[#This Row],[Rating]]=5,"Excellent",Table2[[#This Row],[Rating]]=4,"Good",Table2[[#This Row],[Rating]]=3,"Average",Table2[[#This Row],[Rating]]<=2,"Poor") -> Good | AF19: =Table2[[#This Row],[Cost]]+Table2[[#This Row],[Profit]]+Table2[[#This Row],[ShippingCost]]+Table2[[#This Row],[DeliveryDays]] -> 374.99 | AG19: =Table2[[#This Row],[Profit]]/Table2[[#This Row],[Cost]] -> 0.23844106 | AQ19: Find minimum Quantity sold. | AY19: =MIN(WorkSheet_ANS!$N$2:$N$999) -> 1 | BC19: =MAX(Table2[[#All],[Revenue]]) -> 18384.66 | BD19: =INDEX(Table2[[#All],[Month]],MATCH($BC$19,Table2[[#All],[Revenue]],0),0) -> February
A20: 19 | B20: 2024-12-27 | C20: =YEAR(Table2[[#This Row],[Date]]) -> 2024 | D20: =TEXT(Table2[[#This Row],[Date]],"mmmm") -> December | E20: Sara | F20: East | G20: USA | H20: Mumbai | I20: Electronics | J20: Printer | K20: Distributor | L20: Rep C | M20: 592.47 | N20: 19 | O20: 0.08 | P20: =IF(Table2[[#This Row],[Discount]]>20%,"HIGH","LOW") -> LOW | Q20: 10356.38 | R20: =_xlfn.IFS(Table2[[#This Row],[Revenue]]<1000,"Small",OR(Table2[[#This Row],[Revenue]]>1000,Table2[[#This Row],[Revenue]]<=5000),"Medium",Table2[[#This Row],[Revenue]]>5000,"Large") -> Medium | S20: =IF(Table2[[#This Row],[Revenue]]>3000,"Premium","Not Premium") -> Premium | T20: 8696.16 | U20: 1660.22 | V20: PayPal | W20: Critical | X20: Standard | Y20: 16.1 | Z20: 3 | AA20: =IF(Table2[[#This Row],[DeliveryDays]]<=3,"FAST DELIVERY","LATE DELIVERY") -> FAST DELIVERY | AB20: Consumer | AC20: Yes | AD20: 5 | AE20: =_xlfn.IFS(Table2[[#This Row],[Rating]]=5,"Excellent",Table2[[#This Row],[Rating]]=4,"Good",Table2[[#This Row],[Rating]]=3,"Average",Table2[[#This Row],[Rating]]<=2,"Poor") -> Excellent | AF20: =Table2[[#This Row],[Cost]]+Table2[[#This Row],[Profit]]+Table2[[#This Row],[ShippingCost]]+Table2[[#This Row],[DeliveryDays]] -> 10375.48 | AG20: =Table2[[#This Row],[Profit]]/Table2[[#This Row],[Cost]] -> 0.19091415
A21: 20 | B21: 2023-12-07 | C21: =YEAR(Table2[[#This Row],[Date]]) -> 2023 | D21: =TEXT(Table2[[#This Row],[Date]],"mmmm") -> December | E21: Riya | F21: East | G21: UK | H21: Sydney | I21: Sports | J21: Jacket | K21: Retail | L21: Rep C | M21: 548.16 | N21: 1 | O21: 0.21 | P21: =IF(Table2[[#This Row],[Discount]]>20%,"HIGH","LOW") -> HIGH | Q21: 433.05 | R21: =_xlfn.IFS(Table2[[#This Row],[Revenue]]<1000,"Small",OR(Table2[[#This Row],[Revenue]]>1000,Table2[[#This Row],[Revenue]]<=5000),"Medium",Table2[[#This Row],[Revenue]]>5000,"Large") -> Small | S21: =IF(Table2[[#This Row],[Revenue]]>3000,"Premium","Not Premium") -> Not Premium | T21: 297.44 | U21: 135.61 | V21: Credit Card | W21: Medium | X21: Same Day | Y21: 33.45 | Z21: 7 | AA21: =IF(Table2[[#This Row],[DeliveryDays]]<=3,"FAST DELIVERY","LATE DELIVERY") -> LATE DELIVERY | AB21: Corporate | AC21: Yes | AD21: 3 | AE21: =_xlfn.IFS(Table2[[#This Row],[Rating]]=5,"Excellent",Table2[[#This Row],[Rating]]=4,"Good",Table2[[#This Row],[Rating]]=3,"Average",Table2[[#This Row],[Rating]]<=2,"Poor") -> Average | AF21: =Table2[[#This Row],[Cost]]+Table2[[#This Row],[Profit]]+Table2[[#This Row],[ShippingCost]]+Table2[[#This Row],[DeliveryDays]] -> 473.5 | AG21: =Table2[[#This Row],[Profit]]/Table2[[#This Row],[Cost]] -> 0.45592388 | AQ21: Calculate Total Revenue. | AY21: =SUM(WorkSheet_ANS!$Q$2:$Q$999) -> 4400793.2 | BC21: Find best performing month. | BF21: =INDEX(BC2:BC14,MATCH(MAX(BE2:BE14),BE2:BE14,0),0) -> July
A22: 21 | B22: 2024-08-23 | C22: =YEAR(Table2[[#This Row],[Date]]) -> 2024 | D22: =TEXT(Table2[[#This Row],[Date]],"mmmm") -> August | E22: Riya | F22: West | G22: USA | H22: Sydney | I22: Clothing | J22: Keyboard | K22: Retail | L22: Rep B | M22: 839.45 | N22: 6 | O22: 0.3 | P22: =IF(Table2[[#This Row],[Discount]]>20%,"HIGH","LOW") -> HIGH | Q22: 3525.69 | R22: =_xlfn.IFS(Table2[[#This Row],[Revenue]]<1000,"Small",OR(Table2[[#This Row],[Revenue]]>1000,Table2[[#This Row],[Revenue]]<=5000),"Medium",Table2[[#This Row],[Revenue]]>5000,"Large") -> Medium | S22: =IF(Table2[[#This Row],[Revenue]]>3000,"Premium","Not Premium") -> Premium | T22: 2289.81 | U22: 1235.88 | V22: Cash | W22: High | X22: Same Day | Y22: 49.92 | Z22: 1 | AA22: =IF(Table2[[#This Row],[DeliveryDays]]<=3,"FAST DELIVERY","LATE DELIVERY") -> FAST DELIVERY | AB22: Corporate | AC22: No | AD22: 3 | AE22: =_xlfn.IFS(Table2[[#This Row],[Rating]]=5,"Excellent",Table2[[#This Row],[Rating]]=4,"Good",Table2[[#This Row],[Rating]]=3,"Average",Table2[[#This Row],[Rating]]<=2,"Poor") -> Average | AF22: =Table2[[#This Row],[Cost]]+Table2[[#This Row],[Profit]]+Table2[[#This Row],[ShippingCost]]+Table2[[#This Row],[DeliveryDays]] -> 3576.61 | AG22: =Table2[[#This Row],[Profit]]/Table2[[#This Row],[Cost]] -> 0.53973037
A23: 22 | B23: 2024-11-14 | C23: =YEAR(Table2[[#This Row],[Date]]) -> 2024 | D23: =TEXT(Table2[[#This Row],[Date]],"mmmm") -> November | E23: Sara | F23: South | G23: Canada | H23: Mumbai | I23: Electronics | J23: Football | K23: Online | L23: Rep C | M23: 433.56 | N23: 16 | O23: 0.08 | P23: =IF(Table2[[#This Row],[Discount]]>20%,"HIGH","LOW") -> LOW | Q23: 6382 | R23: =_xlfn.IFS(Table2[[#This Row],[Revenue]]<1000,"Small",OR(Table2[[#This Row],[Revenue]]>1000,Table2[[#This Row],[Revenue]]<=5000),"Medium",Table2[[#This Row],[Revenue]]>5000,"Large") -> Medium | S23: =IF(Table2[[#This Row],[Revenue]]>3000,"Premium","Not Premium") -> Premium | T23: 4078.68 | U23: 2303.32 | V23: Cash | W23: Medium | X23: Same Day | Y23: 5.44 | Z23: 8 | AA23: =IF(Table2[[#This Row],[DeliveryDays]]<=3,"FAST DELIVERY","LATE DELIVERY") -> LATE DELIVERY | AB23: Consumer | AC23: No | AD23: 2 | AE23: =_xlfn.IFS(Table2[[#This Row],[Rating]]=5,"Excellent",Table2[[#This Row],[Rating]]=4,"Good",Table2[[#This Row],[Rating]]=3,"Average",Table2[[#This Row],[Rating]]<=2,"Poor") -> Poor | AF23: =Table2[[#This Row],[Cost]]+Table2[[#This Row],[Profit]]+Table2[[#This Row],[ShippingCost]]+Table2[[#This Row],[DeliveryDays]] -> 6395.44 | AG23: =Table2[[#This Row],[Profit]]/Table2[[#This Row],[Cost]] -> 0.56472192 | AQ23: Calculate Total Cost. | AY23: =SUM(WorkSheet_ANS!$T$2:$T$999) -> 3069234.7 | BC23: Find worst performing month. | BF23: =INDEX(BC2:BC14,MATCH(MIN(BE2:BE14),BE2:BE14,0),0) -> April
A24: 23 | B24: 2023-01-15 | C24: =YEAR(Table2[[#This Row],[Date]]) -> 2023 | D24: =TEXT(Table2[[#This Row],[Date]],"mmmm") -> January | E24: Riya | F24: East | G24: Canada | H24: Sydney | I24: Sports | J24: Jacket | K24: Retail | L24: Rep A | M24: 769.36 | N24: 18 | O24: 0.15 | P24: =IF(Table2[[#This Row],[Discount]]>20%,"HIGH","LOW") -> LOW | Q24: 11771.21 | R24: =_xlfn.IFS(Table2[[#This Row],[Revenue]]<1000,"Small",OR(Table2[[#This Row],[Revenue]]>1000,Table2[[#This Row],[Revenue]]<=5000),"Medium",Table2[[#This Row],[Revenue]]>5000,"Large") -> Medium | S24: =IF(Table2[[#This Row],[Revenue]]>3000,"Premium","Not Premium") -> Premium | T24: 8865.18 | U24: 2906.03 | V24: PayPal | W24: Critical | X24: Same Day | Y24: 44.03 | Z24: 3 | AA24: =IF(Table2[[#This Row],[DeliveryDays]]<=3,"FAST DELIVERY","LATE DELIVERY") -> FAST DELIVERY | AB24: Consumer | AC24: Yes | AD24: 3 | AE24: =_xlfn.IFS(Table2[[#This Row],[Rating]]=5,"Excellent",Table2[[#This Row],[Rating]]=4,"Good",Table2[[#This Row],[Rating]]=3,"Average",Table2[[#This Row],[Rating]]<=2,"Poor") -> Average | AF24: =Table2[[#This Row],[Cost]]+Table2[[#This Row],[Profit]]+Table2[[#This Row],[ShippingCost]]+Table2[[#This Row],[DeliveryDays]] -> 11818.24 | AG24: =Table2[[#This Row],[Profit]]/Table2[[#This Row],[Cost]] -> 0.32780271
A25: 24 | B25: 2023-03-11 | C25: =YEAR(Table2[[#This Row],[Date]]) -> 2023 | D25: =TEXT(Table2[[#This Row],[Date]],"mmmm") -> March | E25: Rahul | F25: West | G25: Canada | H25: Berlin | I25: Furniture | J25: Chair | K25: Retail | L25: Rep A | M25: 735.29 | N25: 14 | P25: =IF(Table2[[#This Row],[Discount]]>20%,"HIGH","LOW") -> LOW | Q25: 7205.84 | R25: =_xlfn.IFS(Table2[[#This Row],[Revenue]]<1000,"Small",OR(Table2[[#This Row],[Revenue]]>1000,Table2[[#This Row],[Revenue]]<=5000),"Medium",Table2[[#This Row],[Revenue]]>5000,"Large") -> Medium | S25: =IF(Table2[[#This Row],[Revenue]]>3000,"Premium","Not Premium") -> Premium | T25: 6440.47 | U25: 765.37 | V25: PayPal | W25: High | X25: Same Day | Y25: 22.18 | Z25: 4 | AA25: =IF(Table2[[#This Row],[DeliveryDays]]<=3,"FAST DELIVERY","LATE DELIVERY") -> LATE DELIVERY | AB25: Corporate | AC25: Yes | AD25: 1 | AE25: =_xlfn.IFS(Table2[[#This Row],[Rating]]=5,"Excellent",Table2[[#This Row],[Rating]]=4,"Good",Table2[[#This Row],[Rating]]=3,"Average",Table2[[#This Row],[Rating]]<=2,"Poor") -> Poor | AF25: =Table2[[#This Row],[Cost]]+Table2[[#This Row],[Profit]]+Table2[[#This Row],[ShippingCost]]+Table2[[#This Row],[DeliveryDays]] -> 7232.02 | AG25: =Table2[[#This Row],[Profit]]/Table2[[#This Row],[Cost]] -> 0.1188376 | AQ25: Calculate Total Profit. | AY25: =SUM(WorkSheet_ANS!$U$2:$U$999) -> 1331558.5 | BC25: Identify lowest profit margin product. | BI25: =MIN(Table2[Profit Margin]) -> 0.11236077
A26: 25 | B26: 2024-08-24 | C26: =YEAR(Table2[[#This Row],[Date]]) -> 2024 | D26: =TEXT(Table2[[#This Row],[Date]],"mmmm") -> August | E26: Priya | F26: South | G26: Germany | H26: Delhi | I26: Electronics | J26: T-Shirt | K26: Retail | L26: Rep B | M26: 823.06 | N26: 6 | O26: 0.1 | P26: =IF(Table2[[#This Row],[Discount]]>20%,"HIGH","LOW") -> LOW | Q26: 4444.52 | R26: =_xlfn.IFS(Table2[[#This Row],[Revenue]]<1000,"Small",OR(Table2[[#This Row],[Revenue]]>1000,Table2[[#This Row],[Revenue]]<=5000),"Medium",Table2[[#This Row],[Revenue]]>5000,"Large") -> Medium | S26: =IF(Table2[[#This Row],[Revenue]]>3000,"Premium","Not Premium") -> Premium | T26: 3447.91 | U26: 996.61 | V26: PayPal | W26: Medium | X26: Express | Y26: 10.2 | Z26: 1 | AA26: =IF(Table2[[#This Row],[DeliveryDays]]<=3,"FAST DELIVERY","LATE DELIVERY") -> FAST DELIVERY | AB26: Consumer | AC26: Yes | AD26: 5 | AE26: =_xlfn.IFS(Table2[[#This Row],[Rating]]=5,"Excellent",Table2[[#This Row],[Rating]]=4,"Good",Table2[[#This Row],[Rating]]=3,"Average",Table2[[#This Row],[Rating]]<=2,"Poor") -> Excellent | AF26: =Table2[[#This Row],[Cost]]+Table2[[#This Row],[Profit]]+Table2[[#This Row],[ShippingCost]]+Table2[[#This Row],[DeliveryDays]] -> 4455.72 | AG26: =Table2[[#This Row],[Profit]]/Table2[[#This Row],[Cost]] -> 0.28904757
A27: 26 | B27: 2024-07-01 | C27: =YEAR(Table2[[#This Row],[Date]]) -> 2024 | D27: =TEXT(Table2[[#This Row],[Date]],"mmmm") -> July | E27: Sophia | F27: North | G27: UK | H27: Mumbai | I27: Clothing | J27: Laptop | K27: Online | L27: Rep E | M27: 710.55 | N27: 10 | O27: 0.09 | P27: =IF(Table2[[#This Row],[Discount]]>20%,"HIGH","LOW") -> LOW | Q27: 6466.01 | R27: =_xlfn.IFS(Table2[[#This Row],[Revenue]]<1000,"Small",OR(Table2[[#This Row],[Revenue]]>1000,Table2[[#This Row],[Revenue]]<=5000),"Medium",Table2[[#This Row],[Revenue]]>5000,"Large") -> Medium | S27: =IF(Table2[[#This Row],[Revenue]]>3000,"Premium","Not Premium") -> Premium | T27: 5293.17 | U27: 1172.84 | V27: Credit Card | W27: Medium | X27: Standard | Y27: 10.52 | Z27: 7 | AA27: =IF(Table2[[#This Row],[DeliveryDays]]<=3,"FAST DELIVERY","LATE DELIVERY") -> LATE DELIVERY | AB27: Consumer | AC27: Yes | AD27: 2 | AE27: =_xlfn.IFS(Table2[[#This Row],[Rating]]=5,"Excellent",Table2[[#This Row],[Rating]]=4,"Good",Table2[[#This Row],[Rating]]=3,"Average",Table2[[#This Row],[Rating]]<=2,"Poor") -> Poor | AF27: =Table2[[#This Row],[Cost]]+Table2[[#This Row],[Profit]]+Table2[[#This Row],[ShippingCost]]+Table2[[#This Row],[DeliveryDays]] -> 6483.53 | AG27: =Table2[[#This Row],[Profit]]/Table2[[#This Row],[Cost]] -> 0.22157611 | AQ27: Calculate Average Profit per Order. | AY27: =AVERAGE(WorkSheet_ANS!$U$2:$U$999) -> 1334.227 | BC27: Identify highest profit margin product. | BI27: =MAX(Table2[Profit Margin]) -> 0.99627411
A28: 27 | B28: 2023-04-27 | C28: =YEAR(Table2[[#This Row],[Date]]) -> 2023 | D28: =TEXT(Table2[[#This Row],[Date]],"mmmm") -> April | E28: Arjun | F28: North | G28: India | H28: New York | I28: Electronics | J28: Football | K28: Online | L28: Rep E | M28: 600.43 | N28: 17 | O28: 0.17 | P28: =IF(Table2[[#This Row],[Discount]]>20%,"HIGH","LOW") -> LOW | Q28: 8472.07 | R28: =_xlfn.IFS(Table2[[#This Row],[Revenue]]<1000,"Small",OR(Table2[[#This Row],[Revenue]]>1000,Table2[[#This Row],[Revenue]]<=5000),"Medium",Table2[[#This Row],[Revenue]]>5000,"Large") -> Medium | S28: =IF(Table2[[#This Row],[Revenue]]>3000,"Premium","Not Premium") -> Premium | T28: 4854.92 | U28: 3617.15 | V28: Credit Card | W28: Low | X28: Same Day | Y28: 12.96 | Z28: 6 | AA28: =IF(Table2[[#This Row],[DeliveryDays]]<=3,"FAST DELIVERY","LATE DELIVERY") -> LATE DELIVERY | AB28: Home Office | AC28: Yes | AD28: 5 | AE28: =_xlfn.IFS(Table2[[#This Row],[Rating]]=5,"Excellent",Table2[[#This Row],[Rating]]=4,"Good",Table2[[#This Row],[Rating]]=3,"Average",Table2[[#This Row],[Rating]]<=2,"Poor") -> Excellent | AF28: =Table2[[#This Row],[Cost]]+Table2[[#This Row],[Profit]]+Table2[[#This Row],[ShippingCost]]+Table2[[#This Row],[DeliveryDays]] -> 8491.03 | AG28: =Table2[[#This Row],[Profit]]/Table2[[#This Row],[Cost]] -> 0.74504832
A29: 28 | B29: 2023-05-19 | C29: =YEAR(Table2[[#This Row],[Date]]) -> 2023 | D29: =TEXT(Table2[[#This Row],[Date]],"mmmm") -> May | E29: Amit | F29: North | G29: India | H29: Toronto | I29: Electronics | J29: T-Shirt | K29: Retail | L29: Rep D | M29: 697.99 | N29: 7 | O29: 0.1 | P29: =IF(Table2[[#This Row],[Discount]]>20%,"HIGH","LOW") -> LOW | Q29: 4397.34 | R29: =_xlfn.IFS(Table2[[#This Row],[Revenue]]<1000,"Small",OR(Table2[[#This Row],[Revenue]]>1000,Table2[[#This Row],[Revenue]]<=5000),"Medium",Table2[[#This Row],[Revenue]]>5000,"Large") -> Medium | S29: =IF(Table2[[#This Row],[Revenue]]>3000,"Premium","Not Premium") -> Premium | T29: 2823.58 | U29: 1573.76 | V29: UPI | W29: Critical | X29: Same Day | Y29: 27.37 | Z29: 1 | AA29: =IF(Table2[[#This Row],[DeliveryDays]]<=3,"FAST DELIVERY","LATE DELIVERY") -> FAST DELIVERY | AB29: Consumer | AC29: Yes | AD29: 5 | AE29: =_xlfn.IFS(Table2[[#This Row],[Rating]]=5,"Excellent",Table2[[#This Row],[Rating]]=4,"Good",Table2[[#This Row],[Rating]]=3,"Average",Table2[[#This Row],[Rating]]<=2,"Poor") -> Excellent | AF29: =Table2[[#This Row],[Cost]]+Table2[[#This Row],[Profit]]+Table2[[#This Row],[ShippingCost]]+Table2[[#This Row],[DeliveryDays]] -> 4425.71 | AG29: =Table2[[#This Row],[Profit]]/Table2[[#This Row],[Cost]] -> 0.55736335 | AQ29: Calculate Average Revenue per Order. | AY29: =AVERAGE(WorkSheet_ANS!$Q$2:$Q$999) -> 4409.6124
A30: 29 | B30: 2024-07-30 | C30: =YEAR(Table2[[#This Row],[Date]]) -> 2024 | D30: =TEXT(Table2[[#This Row],[Date]],"mmmm") -> July | E30: Arjun | F30: East | G30: UK | H30: Sydney | I30: Electronics | J30: Laptop | K30: Online | L30: Rep E | M30: 701.56 | N30: 3 | O30: 0.14 | P30: =IF(Table2[[#This Row],[Discount]]>20%,"HIGH","LOW") -> LOW | Q30: 1810.02 | R30: =_xlfn.IFS(Table2[[#This Row],[Revenue]]<1000,"Small",OR(Table2[[#This Row],[Revenue]]>1000,Table2[[#This Row],[Revenue]]<=5000),"Medium",Table2[[#This Row],[Revenue]]>5000,"Large") -> Medium | S30: =IF(Table2[[#This Row],[Revenue]]>3000,"Premium","Not Premium") -> Not Premium | T30: 1148.8 | U30: 661.22 | V30: PayPal | W30: High | X30: Standard | Y30: 37.53 | Z30: 7 | AA30: =IF(Table2[[#This Row],[DeliveryDays]]<=3,"FAST DELIVERY","LATE DELIVERY") -> LATE DELIVERY | AB30: Corporate | AC30: No | AD30: 3 | AE30: =_xlfn.IFS(Table2[[#This Row],[Rating]]=5,"Excellent",Table2[[#This Row],[Rating]]=4,"Good",Table2[[#This Row],[Rating]]=3,"Average",Table2[[#This Row],[Rating]]<=2,"Poor") -> Average | AF30: =Table2[[#This Row],[Cost]]+Table2[[#This Row],[Profit]]+Table2[[#This Row],[ShippingCost]]+Table2[[#This Row],[DeliveryDays]] -> 1854.55 | AG30: =Table2[[#This Row],[Profit]]/Table2[[#This Row],[Cost]] -> 0.57557451
A31: 30 | B31: 2023-04-09 | C31: =YEAR(Table2[[#This Row],[Date]]) -> 2023 | D31: =TEXT(Table2[[#This Row],[Date]],"mmmm") -> April | E31: Anita | F31: East | G31: India | H31: Mumbai | I31: Furniture | J31: T-Shirt | K31: Online | L31: Rep E | M31: 471.7 | N31: 14 | O31: 0.27 | P31: =IF(Table2[[#This Row],[Discount]]>20%,"HIGH","LOW") -> HIGH | Q31: 4820.77 | R31: =_xlfn.IFS(Table2[[#This Row],[Revenue]]<1000,"Small",OR(Table2[[#This Row],[Revenue]]>1000,Table2[[#This Row],[Revenue]]<=5000),"Medium",Table2[[#This Row],[Revenue]]>5000,"Large") -> Medium | S31: =IF(Table2[[#This Row],[Revenue]]>3000,"Premium","Not Premium") -> Premium | T31: 3546.14 | U31: 1274.63 | V31: Bank Transfer | W31: Medium | X31: Express | Y31: 29.81 | Z31: 2 | AA31: =IF(Table2[[#This Row],[DeliveryDays]]<=3,"FAST DELIVERY","LATE DELIVERY") -> FAST DELIVERY | AB31: Consumer | AC31: No | AD31: 5 | AE31: =_xlfn.IFS(Table2[[#This Row],[Rating]]=5,"Excellent",Table2[[#This Row],[Rating]]=4,"Good",Table2[[#This Row],[Rating]]=3,"Average",Table2[[#This Row],[Rating]]<=2,"Poor") -> Excellent | AF31: =Table2[[#This Row],[Cost]]+Table2[[#This Row],[Profit]]+Table2[[#This Row],[ShippingCost]]+Table2[[#This Row],[DeliveryDays]] -> 4852.58 | AG31: =Table2[[#This Row],[Profit]]/Table2[[#This Row],[Cost]] -> 0.35944153 | AQ31: Show only Electronics products.
A32: 31 | B32: 2023-09-10 | C32: =YEAR(Table2[[#This Row],[Date]]) -> 2023 | D32: =TEXT(Table2[[#This Row],[Date]],"mmmm") -> September | E32: David | F32: East | G32: Germany | H32: New York | I32: Sports | J32: T-Shirt | K32: Distributor | L32: Rep E | M32: 825.37 | N32: 11 | O32: 0.09 | P32: =IF(Table2[[#This Row],[Discount]]>20%,"HIGH","LOW") -> LOW | Q32: 8261.95 | R32: =_xlfn.IFS(Table2[[#This Row],[Revenue]]<1000,"Small",OR(Table2[[#This Row],[Revenue]]>1000,Table2[[#This Row],[Revenue]]<=5000),"Medium",Table2[[#This Row],[Revenue]]>5000,"Large") -> Medium | S32: =IF(Table2[[#This Row],[Revenue]]>3000,"Premium","Not Premium") -> Premium | T32: 6670.56 | U32: 1591.39 | V32: PayPal | W32: Critical | X32: Express | Y32: 42.08 | Z32: 8 | AA32: =IF(Table2[[#This Row],[DeliveryDays]]<=3,"FAST DELIVERY","LATE DELIVERY") -> LATE DELIVERY | AB32: Corporate | AC32: No | AD32: 1 | AE32: =_xlfn.IFS(Table2[[#This Row],[Rating]]=5,"Excellent",Table2[[#This Row],[Rating]]=4,"Good",Table2[[#This Row],[Rating]]=3,"Average",Table2[[#This Row],[Rating]]<=2,"Poor") -> Poor | AF32: =Table2[[#This Row],[Cost]]+Table2[[#This Row],[Profit]]+Table2[[#This Row],[ShippingCost]]+Table2[[#This Row],[DeliveryDays]] -> 8312.03 | AG32: =Table2[[#This Row],[Profit]]/Table2[[#This Row],[Cost]] -> 0.23856918
A33: 32 | B33: 2023-03-27 | C33: =YEAR(Table2[[#This Row],[Date]]) -> 2023 | D33: =TEXT(Table2[[#This Row],[Date]],"mmmm") -> March | E33: Amit | F33: West | G33: UK | H33: Toronto | I33: Clothing | J33: Laptop | K33: Retail | L33: Rep B | M33: 108.96 | N33: 14 | O33: 0.14 | P33: =IF(Table2[[#This Row],[Discount]]>20%,"HIGH","LOW") -> LOW | Q33: 1311.88 | R33: =_xlfn.IFS(Table2[[#This Row],[Revenue]]<1000,"Small",OR(Table2[[#This Row],[Revenue]]>1000,Table2[[#This Row],[Revenue]]<=5000),"Medium",Table2[[#This Row],[Revenue]]>5000,"Large") -> Medium | S33: =IF(Table2[[#This Row],[Revenue]]>3000,"Premium","Not Premium") -> Not Premium | T33: 872.57 | U33: 439.31 | V33: Credit Card | W33: Low | X33: Standard | Y33: 14.45 | Z33: 2 | AA33: =IF(Table2[[#This Row],[DeliveryDays]]<=3,"FAST DELIVERY","LATE DELIVERY") -> FAST DELIVERY | AB33: Consumer | AC33: No | AD33: 5 | AE33: =_xlfn.IFS(Table2[[#This Row],[Rating]]=5,"Excellent",Table2[[#This Row],[Rating]]=4,"Good",Table2[[#This Row],[Rating]]=3,"Average",Table2[[#This Row],[Rating]]<=2,"Poor") -> Excellent | AF33: =Table2[[#This Row],[Cost]]+Table2[[#This Row],[Profit]]+Table2[[#This Row],[ShippingCost]]+Table2[[#This Row],[DeliveryDays]] -> 1328.33 | AG33: =Table2[[#This Row],[Profit]]/Table2[[#This Row],[Cost]] -> 0.50346677 | AQ33: ProductCategory
A34: 33 | B34: 2024-03-16 | C34: =YEAR(Table2[[#This Row],[Date]]) -> 2024 | D34: =TEXT(Table2[[#This Row],[Date]],"mmmm") -> March | E34: Arjun | F34: West | G34: India | H34: New York | I34: Furniture | J34: Jacket | K34: Distributor | L34: Rep D | M34: 103.94 | N34: 4 | O34: 0.15 | P34: =IF(Table2[[#This Row],[Discount]]>20%,"HIGH","LOW") -> LOW | Q34: 353.4 | R34: =_xlfn.IFS(Table2[[#This Row],[Revenue]]<1000,"Small",OR(Table2[[#This Row],[Revenue]]>1000,Table2[[#This Row],[Revenue]]<=5000),"Medium",Table2[[#This Row],[Revenue]]>5000,"Large") -> Small | S34: =IF(Table2[[#This Row],[Revenue]]>3000,"Premium","Not Premium") -> Not Premium | T34: 206.51 | U34: 146.89 | V34: Credit Card | W34: Low | X34: Same Day | Y34: 29.93 | Z34: 3 | AA34: =IF(Table2[[#This Row],[DeliveryDays]]<=3,"FAST DELIVERY","LATE DELIVERY") -> FAST DELIVERY | AB34: Corporate | AC34: Yes | AD34: 5 | AE34: =_xlfn.IFS(Table2[[#This Row],[Rating]]=5,"Excellent",Table2[[#This Row],[Rating]]=4,"Good",Table2[[#This Row],[Rating]]=3,"Average",Table2[[#This Row],[Rating]]<=2,"Poor") -> Excellent | AF34: =Table2[[#This Row],[Cost]]+Table2[[#This Row],[Profit]]+Table2[[#This Row],[ShippingCost]]+Table2[[#This Row],[DeliveryDays]] -> 386.33 | AG34: =Table2[[#This Row],[Profit]]/Table2[[#This Row],[Cost]] -> 0.71129727 | AQ34: Electronics
A35: 34 | B35: 2024-01-07 | C35: =YEAR(Table2[[#This Row],[Date]]) -> 2024 | D35: =TEXT(Table2[[#This Row],[Date]],"mmmm") -> January | E35: Neha | F35: East | G35: Australia | H35: New York | I35: Sports | J35: Laptop | K35: Distributor | L35: Rep D | M35: 734.65 | N35: 18 | O35: 0.13 | P35: =IF(Table2[[#This Row],[Discount]]>20%,"HIGH","LOW") -> LOW | Q35: 11504.62 | R35: =_xlfn.IFS(Table2[[#This Row],[Revenue]]<1000,"Small",OR(Table2[[#This Row],[Revenue]]>1000,Table2[[#This Row],[Revenue]]<=5000),"Medium",Table2[[#This Row],[Revenue]]>5000,"Large") -> Medium | S35: =IF(Table2[[#This Row],[Revenue]]>3000,"Premium","Not Premium") -> Premium | T35: 9351.84 | U35: 2152.78 | V35: UPI | W35: Low | X35: Same Day | Y35: 41.95 | Z35: 2 | AA35: =IF(Table2[[#This Row],[DeliveryDays]]<=3,"FAST DELIVERY","LATE DELIVERY") -> FAST DELIVERY | AB35: Corporate | AC35: No | AD35: 2 | AE35: =_xlfn.IFS(Table2[[#This Row],[Rating]]=5,"Excellent",Table2[[#This Row],[Rating]]=4,"Good",Table2[[#This Row],[Rating]]=3,"Average",Table2[[#This Row],[Rating]]<=2,"Poor") -> Poor | AF35: =Table2[[#This Row],[Cost]]+Table2[[#This Row],[Profit]]+Table2[[#This Row],[ShippingCost]]+Table2[[#This Row],[DeliveryDays]] -> 11548.57 | AG35: =Table2[[#This Row],[Profit]]/Table2[[#This Row],[Cost]] -> 0.23019855 | BO35: Month
A36: 35 | B36: 2023-12-21 | C36: =YEAR(Table2[[#This Row],[Date]]) -> 2023 | D36: =TEXT(Table2[[#This Row],[Date]],"mmmm") -> December | E36: John | F36: South | G36: Australia | H36: Pune | I36: Office Supplies | J36: Desk | K36: Retail | L36: Rep B | M36: 320.13 | N36: 16 | O36: 0.28 | P36: =IF(Table2[[#This Row],[Discount]]>20%,"HIGH","LOW") -> HIGH | Q36: 3687.9 | R36: =_xlfn.IFS(Table2[[#This Row],[Revenue]]<1000,"Small",OR(Table2[[#This Row],[Revenue]]>1000,Table2[[#This Row],[Revenue]]<=5000),"Medium",Table2[[#This Row],[Revenue]]>5000,"Large") -> Medium | S36: =IF(Table2[[#This Row],[Revenue]]>3000,"Premium","Not Premium") -> Premium | T36: 2965.44 | U36: 722.46 | V36: PayPal | W36: Medium | X36: Standard | Y36: 9.33 | Z36: 8 | AA36: =IF(Table2[[#This Row],[DeliveryDays]]<=3,"FAST DELIVERY","LATE DELIVERY") -> LATE DELIVERY | AB36: Consumer | AC36: Yes | AD36: 4 | AE36: =_xlfn.IFS(Table2[[#This Row],[Rating]]=5,"Excellent",Table2[[#This Row],[Rating]]=4,"Good",Table2[[#This Row],[Rating]]=3,"Average",Table2[[#This Row],[Rating]]<=2,"Poor") -> Good | AF36: =Table2[[#This Row],[Cost]]+Table2[[#This Row],[Profit]]+Table2[[#This Row],[ShippingCost]]+Table2[[#This Row],[DeliveryDays]] -> 3705.23 | AG36: =Table2[[#This Row],[Profit]]/Table2[[#This Row],[Cost]] -> 0.24362658 | AQ36: OrderID | AR36: Date | AS36: CustomerName | AT36: Region | AU36: Country | AV36: City | AW36: ProductCategory | AX36: ProductName | AY36: SalesChannel | AZ36: SalesRep | BA36: UnitPrice | BB36: Quantity | BC36: Discount | BD36: Revenue | BE36: Cost | BF36: Profit | BG36: PaymentMethod | BH36: OrderPriority | BI36: ShipMode | BJ36: ShippingCost | BK36: DeliveryDays | BL36: CustomerSegment | BM36: Returned | BN36: Rating | BO36: 8
A37: 36 | B37: 2024-03-01 | C37: =YEAR(Table2[[#This Row],[Date]]) -> 2024 | D37: =TEXT(Table2[[#This Row],[Date]],"mmmm") -> March | E37: Michael | F37: South | G37: USA | H37: Mumbai | I37: Sports | J37: Keyboard | K37: Retail | L37: Rep D | M37: 478.26 | N37: 8 | O37: 0.1 | P37: =IF(Table2[[#This Row],[Discount]]>20%,"HIGH","LOW") -> LOW | Q37: 3443.47 | R37: =_xlfn.IFS(Table2[[#This Row],[Revenue]]<1000,"Small",OR(Table2[[#This Row],[Revenue]]>1000,Table2[[#This Row],[Revenue]]<=5000),"Medium",Table2[[#This Row],[Revenue]]>5000,"Large") -> Medium | S37: =IF(Table2[[#This Row],[Revenue]]>3000,"Premium","Not Premium") -> Premium | T37: 2982.16 | U37: 461.31 | V37: Bank Transfer | W37: Critical | X37: Express | Y37: 13.54 | Z37: 7 | AA37: =IF(Table2[[#This Row],[DeliveryDays]]<=3,"FAST DELIVERY","LATE DELIVERY") -> LATE DELIVERY | AB37: Consumer | AC37: No | AD37: 1 | AE37: =_xlfn.IFS(Table2[[#This Row],[Rating]]=5,"Excellent",Table2[[#This Row],[Rating]]=4,"Good",Table2[[#This Row],[Rating]]=3,"Average",Table2[[#This Row],[Rating]]<=2,"Poor") -> Poor | AF37: =Table2[[#This Row],[Cost]]+Table2[[#This Row],[Profit]]+Table2[[#This Row],[ShippingCost]]+Table2[[#This Row],[DeliveryDays]] -> 3464.01 | AG37: =Table2[[#This Row],[Profit]]/Table2[[#This Row],[Cost]] -> 0.15468989 | AQ37: 1 | AR37: 2023-08-26 | AS37: Michael | AT37: North | AU37: Canada | AV37: Mumbai | AW37: Electronics | AX37: Jacket | AY37: Retail | AZ37: Rep D | BA37: 576.66 | BB37: 4 | BC37: 0.17 | BD37: 1914.51 | BE37: 1118.63 | BF37: 795.88 | BG37: Bank Transfer | BH37: Medium | BI37: Standard | BJ37: 32.48 | BK37: 10 | BL37: Home Office | BM37: No | BN37: 2 | BO37: 10
A38: 37 | B38: 2024-05-02 | C38: =YEAR(Table2[[#This Row],[Date]]) -> 2024 | D38: =TEXT(Table2[[#This Row],[Date]],"mmmm") -> May | E38: Arjun | F38: South | G38: USA | H38: Delhi | I38: Electronics | J38: T-Shirt | K38: Retail | L38: Rep D | M38: 423.11 | N38: 20 | O38: 0.23 | P38: =IF(Table2[[#This Row],[Discount]]>20%,"HIGH","LOW") -> HIGH | Q38: 6515.89 | R38: =_xlfn.IFS(Table2[[#This Row],[Revenue]]<1000,"Small",OR(Table2[[#This Row],[Revenue]]>1000,Table2[[#This Row],[Revenue]]<=5000),"Medium",Table2[[#This Row],[Revenue]]>5000,"Large") -> Medium | S38: =IF(Table2[[#This Row],[Revenue]]>3000,"Premium","Not Premium") -> Premium | T38: 4640.04 | U38: 1875.85 | V38: Cash | W38: Medium | X38: Same Day | Y38: 31.13 | Z38: 8 | AA38: =IF(Table2[[#This Row],[DeliveryDays]]<=3,"FAST DELIVERY","LATE DELIVERY") -> LATE DELIVERY | AB38: Home Office | AC38: No | AD38: 5 | AE38: =_xlfn.IFS(Table2[[#This Row],[Rating]]=5,"Excellent",Table2[[#This Row],[Rating]]=4,"Good",Table2[[#This Row],[Rating]]=3,"Average",Table2[[#This Row],[Rating]]<=2,"Poor") -> Excellent | AF38: =Table2[[#This Row],[Cost]]+Table2[[#This Row],[Profit]]+Table2[[#This Row],[ShippingCost]]+Table2[[#This Row],[DeliveryDays]] -> 6555.02 | AG38: =Table2[[#This Row],[Profit]]/Table2[[#This Row],[Cost]] -> 0.40427453 | AQ38: 2 | AR38: 2024-10-15 | AS38: Priya | AT38: South | AU38: USA | AV38: Berlin | AW38: Electronics | AX38: Jacket | AY38: Online | AZ38: Rep C | BA38: 447.27 | BB38: 5 | BC38: 0.12 | BD38: 1967.99 | BE38: 1337.43 | BF38: 630.56 | BG38: Credit Card | BH38: Medium | BI38: Same Day | BJ38: 25.58 | BK38: 4 | BL38: Home Office | BM38: No | BN38: 1 | BO38: 6
A39: 38 | B39: 2024-10-31 | C39: =YEAR(Table2[[#This Row],[Date]]) -> 2024 | D39: =TEXT(Table2[[#This Row],[Date]],"mmmm") -> October | E39: Riya | F39: South | G39: India | H39: Toronto | I39: Clothing | J39: T-Shirt | K39: Online | L39: Rep D | M39: 804.65 | N39: 5 | O39: 0.13 | P39: =IF(Table2[[#This Row],[Discount]]>20%,"HIGH","LOW") -> LOW | Q39: 3500.23 | R39: =_xlfn.IFS(Table2[[#This Row],[Revenue]]<1000,"Small",OR(Table2[[#This Row],[Revenue]]>1000,Table2[[#This Row],[Revenue]]<=5000),"Medium",Table2[[#This Row],[Revenue]]>5000,"Large") -> Medium | S39: =IF(Table2[[#This Row],[Revenue]]>3000,"Premium","Not Premium") -> Premium | T39: 2149.83 | U39: 1350.4 | V39: PayPal | W39: Low | X39: Express | Y39: 11.72 | Z39: 1 | AA39: =IF(Table2[[#This Row],[DeliveryDays]]<=3,"FAST DELIVERY","LATE DELIVERY") -> FAST DELIVERY | AB39: Home Office | AC39: Yes | AD39: 2 | AE39: =_xlfn.IFS(Table2[[#This Row],[Rating]]=5,"Excellent",Table2[[#This Row],[Rating]]=4,"Good",Table2[[#This Row],[Rating]]=3,"Average",Table2[[#This Row],[Rating]]<=2,"Poor") -> Poor | AF39: =Table2[[#This Row],[Cost]]+Table2[[#This Row],[Profit]]+Table2[[#This Row],[ShippingCost]]+Table2[[#This Row],[DeliveryDays]] -> 3512.95 | AG39: =Table2[[#This Row],[Profit]]/Table2[[#This Row],[Cost]] -> 0.62814269 | AQ39: 15 | AR39: 2023-06-14 | AS39: Priya | AT39: South | AU39: Canada | AV39: London | AW39: Electronics | AX39: T-Shirt | AY39: Distributor | AZ39: Rep E | BA39: 66.03 | BB39: 4 | BC39: 0.03 | BD39: 256.2 | BE39: 228.6 | BF39: 27.6 | BG39: Bank Transfer | BH39: Low | BI39: Same Day | BJ39: 18.99 | BK39: 4 | BL39: Consumer | BM39: Yes | BN39: 3 | BO39: 12
A40: 39 | B40: 2023-06-11 | C40: =YEAR(Table2[[#This Row],[Date]]) -> 2023 | D40: =TEXT(Table2[[#This Row],[Date]],"mmmm") -> June | E40: Michael | F40: East | G40: Canada | H40: Sydney | I40: Furniture | J40: Monitor | K40: Online | L40: Rep A | M40: 136.05 | N40: 4 | O40: 0.1 | P40: =IF(Table2[[#This Row],[Discount]]>20%,"HIGH","LOW") -> LOW | Q40: 489.78 | R40: =_xlfn.IFS(Table2[[#This Row],[Revenue]]<1000,"Small",OR(Table2[[#This Row],[Revenue]]>1000,Table2[[#This Row],[Revenue]]<=5000),"Medium",Table2[[#This Row],[Revenue]]>5000,"Large") -> Small | S40: =IF(Table2[[#This Row],[Revenue]]>3000,"Premium","Not Premium") -> Not Premium | T40: 257.22 | U40: 232.56 | V40: Credit Card | W40: Low | X40: Standard | Y40: 7.33 | Z40: 6 | AA40: =IF(Table2[[#This Row],[DeliveryDays]]<=3,"FAST DELIVERY","LATE DELIVERY") -> LATE DELIVERY | AB40: Consumer | AC40: Yes | AD40: 4 | AE40: =_xlfn.IFS(Table2[[#This Row],[Rating]]=5,"Excellent",Table2[[#This Row],[Rating]]=4,"Good",Table2[[#This Row],[Rating]]=3,"Average",Table2[[#This Row],[Rating]]<=2,"Poor") -> Good | AF40: =Table2[[#This Row],[Cost]]+Table2[[#This Row],[Profit]]+Table2[[#This Row],[ShippingCost]]+Table2[[#This Row],[DeliveryDays]] -> 503.11 | AG40: =Table2[[#This Row],[Profit]]/Table2[[#This Row],[Cost]] -> 0.90412876 | AQ40: 19 | AR40: 2024-12-27 | AS40: Sara | AT40: East | AU40: USA | AV40: Mumbai | AW40: Electronics | AX40: Printer | AY40: Distributor | AZ40: Rep C | BA40: 592.47 | BB40: 19 | BC40: 0.08 | BD40: 10356.38 | BE40: 8696.16 | BF40: 1660.22 | BG40: PayPal | BH40: Critical | BI40: Standard | BJ40: 16.1 | BK40: 3 | BL40: Consumer | BM40: Yes | BN40: 5 | BO40: 11
...

Sheet PivotTable
A1: Pivot: Revenue by Region. | F1: Pivot: Revenue by Country. | J1: Pivot: Revenue by Product Category. | O1: Pivot: Profit by Product Category. | U1: Pivot: Revenue by Region & Category. | Y1: Pivot: Profit by SalesRep. | AE1: Pivot: Quantity by ProductName. | AK1: Pivot: Revenue by Month. | AP1: Pivot: Revenue by Customer Segment. | AU1: Create Line Chart – Monthly Sales Trend. | BB1: Create Pie Chart – Sales by Region. | BI1: Create Bar Chart – Top 10 Products.
A3: Row Labels | B3: Sum of Revenue | F3: Row Labels | G3: Sum of Revenue | J3: Row Labels | K3: Sum of Revenue | O3: Row Labels | P3: Sum of Profit | U3: Row Labels | V3: Sum of Revenue | Y3: Row Labels | Z3: Sum of Revenue | AE3: Row Labels | AF3: Sum of Quantity | AK3: Row Labels | AL3: Sum of Revenue | AP3: Row Labels | AQ3: Sum of Revenue | AU3: Row Labels | AV3: Sum of SaleValue | BB3: Row Labels | BC3: Sum of SaleValue | BI3: Row Labels | BJ3: Sum of Revenue
